Workbook

Sheet Clean Jamming
A1: Message Number | B1: Subcarrier Spacing | C1: Symbol time | D1: Subcarriers (FFT) | E1: CP length | F1: Average Recieved Power (mW) | G1: Threshold | H1: SNR | I1: Average Signal Power 2 | J1: Average Noise Power
A2: 1 | B2: 976.562 | C2: 0.001024 | D2: 256 | E2: 64 | F2: 0.0472292 | G2: 0 | H2: 16.4875 | I2: -18.9612 | J2: -35.4487
A3: =A2+1 -> 2 | B3: 3906.25 | C3: 0.000256 | D3: 64 | E3: 64 | F3: 0.0554086 | G3: 0 | H3: 16.7195 | I3: -19.0825 | J3: -35.8021
A4: =A3+1 -> 3 | B4: 244.141 | C4: 0.004096 | D4: 1024 | E4: 64 | F4: 0.0484495 | G4: 0 | H4: 13.5636 | I4: -18.8403 | J4: -32.4039
A5: =A4+1 -> 4 | B5: 488.281 | C5: 0.002048 | D5: 512 | E5: 64 | F5: 0.1946 | G5: 0 | H5: 14.049 | I5: -18.8097 | J5: -32.8587
A6: =A5+1 -> 5 | B6: 488.281 | C6: 0.002048 | D6: 512 | E6: 64 | F6: 0.0566096 | G6: 0 | H6: 14.4117 | I6: -18.9871 | J6: -33.3987
A7: =A6+1 -> 6 | B7: 488.281 | C7: 0.002048 | D7: 512 | E7: 64 | F7: 0.0474912 | G7: 0 | H7: 14.5853 | I7: -19.02 | J7: -33.6053
A8: =A7+1 -> 7 | B8: 976.562 | C8: 0.001024 | D8: 256 | E8: 64 | F8: 0.0762173 | G8: 0 | H8: 14.8711 | I8: -19.0604 | J8: -33.9315
A9: =A8+1 -> 8 | B9: 488.281 | C9: 0.002048 | D9: 512 | E9: 64 | F9: 0.194954 | G9: 0 | H9: 14.1401 | I9: -18.9154 | J9: -33.0554
A10: =A9+1 -> 9 | B10: 244.141 | C10: 0.004096 | D10: 1024 | E10: 64 | F10: 0.0406929 | G10: 0 | H10: 14.4367 | I10: -19.0023 | J10: -33.439
A11: =A10+1 -> 10 | B11: 244.141 | C11: 0.004096 | D11: 1024 | E11: 64 | F11: 0.0518343 | G11: 0 | H11: 14.5421 | I11: -19.0287 | J11: -33.5707
A12: =A11+1 -> 11 | B12: 488.281 | C12: 0.002048 | D12: 512 | E12: 64 | F12: 0.0471127 | G12: 0 | H12: 14.7519 | I12: -19.0796 | J12: -33.8315
A13: =A12+1 -> 12 | B13: 488.281 | C13: 0.002048 | D13: 512 | E13: 64 | F13: 0.0252773 | G13: 0 | H13: 14.3626 | I13: -19.0628 | J13: -33.4255
A14: =A13+1 -> 13 | B14: 244.141 | C14: 0.004096 | D14: 1024 | E14: 64 | F14: 0.158089 | G14: 0 | H14: 14.4671 | I14: -19.1147 | J14: -33.5818
... A10072: =A10071+1 -> 10071 | B10072: 244.141 | C10072: 0.004096 | D10072: 1024 | E10072: 64 | F10072: 0.0337538 | G10072: 0 | H10072: 17.3126 | I10072: -18.6091 | J10072: -35.9217

Sheet 0.5m - Barrage J1
A1: Message Number | B1: Subcarrier Spacing | C1: Symbol time | D1: Subcarriers (FFT) | E1: CP length | F1: Average Recieved Power (mW) | G1: Threshold | H1: SNR | I1: Average Signal Power 2 | J1: Average Noise Power
A2: 1 | B2: 488.281 | C2: 0.002048 | D2: 512 | E2: 64 | F2: 270.504 | G2: 1 | H2: -2.44419 | I2: -9.11655 | J2: -6.67236
A3: =A2+1 -> 2 | B3: 488.281 | C3: 0.002048 | D3: 512 | E3: 64 | F3: 263.784 | G3: 1 | H3: -2.31595 | I3: -8.04426 | J3: -5.72831
A4: =A3+1 -> 3 | B4: 488.281 | C4: 0.002048 | D4: 512 | E4: 64 | F4: 252.378 | G4: 1 | H4: -2.0037 | I4: -6.61994 | J4: -4.61624
A5: =A4+1 -> 4 | B5: 244.141 | C5: 0.004096 | D5: 1024 | E5: 64 | F5: 247.315 | G5: 1 | H5: -1.68817 | I5: -5.69075 | J5: -4.00258
A6: =A5+1 -> 5 | B6: 244.141 | C6: 0.004096 | D6: 1024 | E6: 64 | F6: 242.719 | G6: 1 | H6: -1.39727 | I6: -5.02341 | J6: -3.62614
A7: =A6+1 -> 6 | B7: 7812.5 | C7: 0.000128 | D7: 32 | E7: 32 | F7: 255.304 | G7: 1 | H7: -1.27084 | I7: -4.74355 | J7: -3.47271
A8: =A7+1 -> 7 | B8: 488.281 | C8: 0.002048 | D8: 512 | E8: 64 | F8: 264.423 | G8: 1 | H8: -1.04913 | I8: -4.2639 | J8: -3.21477
A9: =A8+1 -> 8 | B9: 488.281 | C9: 0.002048 | D9: 512 | E9: 64 | F9: 273.019 | G9: 1 | H9: -0.861455 | I9: -3.88092 | J9: -3.01946
A10: =A9+1 -> 9 | B10: 488.281 | C10: 0.002048 | D10: 512 | E10: 64 | F10: 277.07 | G10: 1 | H10: -0.776803 | I10: -3.71703 | J10: -2.94023
A11: =A10+1 -> 10 | B11: 3906.25 | C11: 0.000256 | D11: 64 | E11: 32 | F11: 274.282 | G11: 1 | H11: -0.62044 | I11: -3.41254 | J11: -2.7921
A12: =A11+1 -> 11 | B12: 1953.12 | C12: 0.000512 | D12: 128 | E12: 32 | F12: 312.361 | G12: 1 | H12: -0.456484 | I12: -3.14893 | J12: -2.69245
A13: =A12+1 -> 12 | B13: 976.562 | C13: 0.001024 | D13: 256 | E13: 64 | F13: 281.214 | G13: 1 | H13: -0.267859 | I13: -2.94132 | J13: -2.67346
A14: =A13+1 -> 13 | B14: 488.281 | C14: 0.002048 | D14: 512 | E14: 64 | F14: 248.118 | G14: 1 | H14: -0.170929 | I14: -2.85675 | J14: -2.68582
... A141: =A140+1 -> 140 | B141: 976.562 | C141: 0.001024 | D141: 256 | E141: 16 | F141: 275.619 | G141: 1 | H141: 5.3999 | I141: -0.453709 | J141: -5.85361

Sheet 0.5m - Barrage J2
A1: Message Number | B1: Subcarrier Spacing | C1: Symbol time | D1: Subcarriers (FFT) | E1: CP length | F1: Average Recieved Power (mW) | G1: Threshold | H1: SNR | I1: Average Signal Power 2 | J1: Average Noise Power
A2: 1 | B2: 488.281 | C2: 0.002048 | D2: 512 | E2: 64 | F2: 305.078 | G2: 1 | H2: -2.55968 | I2: -8.67767 | J2: -6.11799
A3: =A2+1 -> 2 | B3: 488.281 | C3: 0.002048 | D3: 512 | E3: 64 | F3: 299.445 | G3: 1 | H3: -2.40238 | I3: -7.67609 | J3: -5.27371
A4: =A3+1 -> 3 | B4: 244.141 | C4: 0.004096 | D4: 1024 | E4: 64 | F4: 240.327 | G4: 1 | H4: -2.03056 | I4: -6.40366 | J4: -4.3731
A5: =A4+1 -> 4 | B5: 244.141 | C5: 0.004096 | D5: 1024 | E5: 64 | F5: 226.695 | G5: 1 | H5: -1.68213 | I5: -5.57494 | J5: -3.89281
A6: =A5+1 -> 5 | B6: 244.141 | C6: 0.004096 | D6: 1024 | E6: 64 | F6: 231 | G6: 1 | H6: -1.37817 | I6: -4.9533 | J6: -3.57513
A7: =A6+1 -> 6 | B7: 488.281 | C7: 0.002048 | D7: 512 | E7: 64 | F7: 247.726 | G7: 1 | H7: -1.24419 | I7: -4.68534 | J7: -3.44115
A8: =A7+1 -> 7 | B8: 976.562 | C8: 0.001024 | D8: 256 | E8: 16 | F8: 263.343 | G8: 1 | H8: -1.02274 | I8: -4.20211 | J8: -3.17937
A9: =A8+1 -> 8 | B9: 488.281 | C9: 0.002048 | D9: 512 | E9: 64 | F9: 296.576 | G9: 1 | H9: -0.848094 | I9: -3.78935 | J9: -2.94126
A10: =A9+1 -> 9 | B10: 244.141 | C10: 0.004096 | D10: 1024 | E10: 64 | F10: 306.331 | G10: 1 | H10: -0.771687 | I10: -3.60575 | J10: -2.83406
A11: =A10+1 -> 10 | B11: 488.281 | C11: 0.002048 | D11: 512 | E11: 64 | F11: 290.973 | G11: 1 | H11: -0.610465 | I11: -3.30421 | J11: -2.69375
A12: =A11+1 -> 11 | B12: 488.281 | C12: 0.002048 | D12: 512 | E12: 64 | F12: 287.638 | G12: 1 | H12: -0.433119 | I12: -3.05842 | J12: -2.6253
A13: =A12+1 -> 12 | B13: 488.281 | C13: 0.002048 | D13: 512 | E13: 64 | F13: 275.249 | G13: 1 | H13: -0.240546 | I13: -2.85082 | J13: -2.61028
A14: =A13+1 -> 13 | B14: 488.281 | C14: 0.002048 | D14: 512 | E14: 64 | F14: 259.483 | G14: 1 | H14: -0.14102 | I14: -2.76368 | J14: -2.62266
... A140: =A139+1 -> 139 | B140: 976.562 | C140: 0.001024 | D140: 256 | E140: 16 | F140: 315.734 | G140: 1 | H140: 5.40429 | I140: -0.443413 | J140: -5.8477

Sheet 0.5m - Barrage J3
A1: Message Number | B1: Subcarrier Spacing | C1: Symbol time | D1: Subcarriers (FFT) | E1: CP length | F1: Average Recieved Power (mW) | G1: Threshold | H1: SNR | I1: Average Signal Power 2 | J1: Average Noise Power
A2: =1 -> 1 | B2: 488.281 | C2: 0.002048 | D2: 512 | E2: 64 | F2: 308.007 | G2: 1 | H2: -2.65394 | I2: -8.74019 | J2: -6.08625
A3: =A2+1 -> 2 | B3: 488.281 | C3: 0.002048 | D3: 512 | E3: 64 | F3: 304.49 | G3: 1 | H3: -2.4765 | I3: -7.70734 | J3: -5.23083
A4: =A3+1 -> 3 | B4: 244.141 | C4: 0.004096 | D4: 1024 | E4: 64 | F4: 260.348 | G4: 1 | H4: -2.15161 | I4: -6.55567 | J4: -4.40406
A5: =A4+1 -> 4 | B5: 488.281 | C5: 0.002048 | D5: 512 | E5: 64 | F5: 232.539 | G5: 1 | H5: -1.73715 | I5: -5.57908 | J5: -3.84193
A6: =A5+1 -> 5 | B6: 488.281 | C6: 0.002048 | D6: 512 | E6: 64 | F6: 225.588 | G6: 1 | H6: -1.42517 | I6: -4.97356 | J6: -3.54839
A7: =A6+1 -> 6 | B7: 244.141 | C7: 0.004096 | D7: 1024 | E7: 64 | F7: 236.801 | G7: 1 | H7: -1.288 | I7: -4.71754 | J7: -3.42954
A8: =A7+1 -> 7 | B8: 244.141 | C8: 0.004096 | D8: 1024 | E8: 64 | F8: 255.565 | G8: 1 | H8: -1.05583 | I8: -4.24794 | J8: -3.19211
A9: =A8+1 -> 8 | B9: 976.562 | C9: 0.001024 | D9: 256 | E9: 64 | F9: 287.967 | G9: 1 | H9: -0.879 | I9: -3.83619 | J9: -2.95719
A10: =A9+1 -> 9 | B10: 488.281 | C10: 0.002048 | D10: 512 | E10: 64 | F10: 300.672 | G10: 1 | H10: -0.802806 | I10: -3.65121 | J10: -2.8484
A11: =A10+1 -> 10 | B11: 976.562 | C11: 0.001024 | D11: 256 | E11: 32 | F11: 330.635 | G11: 1 | H11: -0.639183 | I11: -3.35482 | J11: -2.71564
A12: =A11+1 -> 11 | B12: 488.281 | C12: 0.002048 | D12: 512 | E12: 64 | F12: 278.844 | G12: 1 | H12: -0.461589 | I12: -3.12353 | J12: -2.66195
A13: =A12+1 -> 12 | B13: 488.281 | C13: 0.002048 | D13: 512 | E13: 32 | F13: 267.188 | G13: 1 | H13: -0.270521 | I13: -2.92241 | J13: -2.65189
A14: =A13+1 -> 13 | B14: 244.141 | C14: 0.004096 | D14: 1024 | E14: 64 | F14: 257.546 | G14: 1 | H14: -0.172003 | I14: -2.83341 | J14: -2.66141
... A155: =A154+1 -> 154 | B155: 488.281 | C155: 0.002048 | D155: 512 | E155: 64 | F155: 245.915 | G155: 1 | H155: 5.55466 | I155: -0.430977 | J155: -5.98564

Sheet 0.5m - Barrage J4
A1: Message Number | B1: Subcarrier Spacing | C1: Symbol time | D1: Subcarriers (FFT) | E1: CP length | F1: Average Recieved Power (mW) | G1: Threshold | H1: SNR | I1: Average Signal Power 2 | J1: Average Noise Power
A2: 1 | B2: 488.281 | C2: 0.002048 | D2: 512 | E2: 64 | F2: 308.783 | G2: 1 | H2: -2.68382 | I2: -8.68329 | J2: -5.99947
A3: =A2+1 -> 2 | B3: 488.281 | C3: 0.002048 | D3: 512 | E3: 64 | F3: 289.672 | G3: 1 | H3: -2.51869 | I3: -7.63323 | J3: -5.11454
A4: =A3+1 -> 3 | B4: 244.141 | C4: 0.004096 | D4: 1024 | E4: 64 | F4: 266.734 | G4: 1 | H4: -2.14474 | I4: -6.28593 | J4: -4.14119
A5: =A4+1 -> 4 | B5: 488.281 | C5: 0.002048 | D5: 512 | E5: 64 | F5: 255.735 | G5: 1 | H5: -1.78155 | I5: -5.44048 | J5: -3.65893
A6: =A5+1 -> 5 | B6: 488.281 | C6: 0.002048 | D6: 512 | E6: 64 | F6: 235.037 | G6: 1 | H6: -1.45803 | I6: -4.84777 | J6: -3.38974
A7: =A6+1 -> 6 | B7: 488.281 | C7: 0.002048 | D7: 512 | E7: 64 | F7: 240.424 | G7: 1 | H7: -1.31621 | I7: -4.60329 | J7: -3.28709
A8: =A7+1 -> 7 | B8: 488.281 | C8: 0.002048 | D8: 512 | E8: 64 | F8: 251.812 | G8: 1 | H8: -1.07145 | I8: -4.17632 | J8: -3.10487
A9: =A8+1 -> 8 | B9: 976.562 | C9: 0.001024 | D9: 256 | E9: 64 | F9: 273.974 | G9: 1 | H9: -0.87913 | I9: -3.79211 | J9: -2.91298
A10: =A9+1 -> 9 | B10: 3906.25 | C10: 0.000256 | D10: 64 | E10: 32 | F10: 288.14 | G10: 1 | H10: -0.799354 | I10: -3.61028 | J10: -2.81093
A11: =A10+1 -> 10 | B11: 488.281 | C11: 0.002048 | D11: 512 | E11: 64 | F11: 332.306 | G11: 1 | H11: -0.642079 | I11: -3.2884 | J11: -2.64632
A12: =A11+1 -> 11 | B12: 488.281 | C12: 0.002048 | D12: 512 | E12: 64 | F12: 313.201 | G12: 1 | H12: -0.4692 | I12: -3.02662 | J12: -2.55742
A13: =A12+1 -> 12 | B13: 488.281 | C13: 0.002048 | D13: 512 | E13: 64 | F13: 286.36 | G13: 1 | H13: -0.273111 | I13: -2.82093 | J13: -2.54782
A14: =A13+1 -> 13 | B14: 488.281 | C14: 0.002048 | D14: 512 | E14: 64 | F14: 268.007 | G14: 1 | H14: -0.173253 | I14: -2.7342 | J14: -2.56095
... A141: =A140+1 -> 140 | B141: 244.141 | C141: 0.004096 | D141: 1024 | E141: 64 | F141: 301.837 | G141: 1 | H141: 5.36028 | I141: -0.453323 | J141: -5.81361

Sheet 0.5m - Barrage J5
A1: Message Number | B1: Subcarrier Spacing | C1: Symbol time | D1: Subcarriers (FFT) | E1: CP length | F1: Average Recieved Power (mW) | G1: Threshold | H1: SNR | I1: Average Signal Power 2 | J1: Average Noise Power
A2: 1 | B2: 488.281 | C2: 0.002048 | D2: 512 | E2: 64 | F2: 155.22 | G2: 1 | H2: -2.16174 | I2: -12.9793 | J2: -10.8175
A3: =A2+1 -> 2 | B3: 488.281 | C3: 0.002048 | D3: 512 | E3: 64 | F3: 309.267 | G3: 1 | H3: -2.53741 | I3: -8.6184 | J3: -6.08099
A4: =A3+1 -> 3 | B4: 488.281 | C4: 0.002048 | D4: 512 | E4: 64 | F4: 307.722 | G4: 1 | H4: -2.40549 | I4: -7.58519 | J4: -5.1797
A5: =A4+1 -> 4 | B5: 244.141 | C5: 0.004096 | D5: 1024 | E5: 64 | F5: 279.077 | G5: 1 | H5: -2.05925 | I5: -6.2547 | J5: -4.19545
A6: =A5+1 -> 5 | B6: 244.141 | C6: 0.004096 | D6: 1024 | E6: 64 | F6: 257.699 | G6: 1 | H6: -1.71091 | I6: -5.40792 | J6: -3.69701
A7: =A6+1 -> 6 | B7: 244.141 | C7: 0.004096 | D7: 1024 | E7: 64 | F7: 238.463 | G7: 1 | H7: -1.39487 | I7: -4.81715 | J7: -3.42228
A8: =A7+1 -> 7 | B8: 488.281 | C8: 0.002048 | D8: 512 | E8: 64 | F8: 234.072 | G8: 1 | H8: -1.25439 | I8: -4.57945 | J8: -3.32506
A9: =A8+1 -> 8 | B9: 976.562 | C9: 0.001024 | D9: 256 | E9: 64 | F9: 233.187 | G9: 1 | H9: -1.01504 | I9: -4.16166 | J9: -3.14662
A10: =A9+1 -> 9 | B10: 1953.12 | C10: 0.000512 | D10: 128 | E10: 32 | F10: 265.915 | G10: 1 | H10: -0.825097 | I10: -3.78999 | J10: -2.96489
A11: =A10+1 -> 10 | B11: 244.141 | C11: 0.004096 | D11: 1024 | E11: 64 | F11: 280.566 | G11: 1 | H11: -0.743036 | I11: -3.61514 | J11: -2.8721
A12: =A11+1 -> 11 | B12: 488.281 | C12: 0.002048 | D12: 512 | E12: 64 | F12: 316.047 | G12: 1 | H12: -0.581472 | I12: -3.31133 | J12: -2.72985
A13: =A12+1 -> 12 | B13: 244.141 | C13: 0.004096 | D13: 1024 | E13: 64 | F13: 280.859 | G13: 1 | H13: -0.40369 | I13: -3.08572 | J13: -2.68203
A14: =A13+1 -> 13 | B14: 488.281 | C14: 0.002048 | D14: 512 | E14: 32 | F14: 261.596 | G14: 1 | H14: -0.215891 | I14: -2.90371 | J14: -2.68782
... A143: =A142+1 -> 142 | B143: 488.281 | C143: 0.002048 | D143: 512 | E143: 64 | F143: 267.986 | G143: 1 | H143: 5.46881 | I143: -0.433429 | J143: -5.90223

Sheet 0.5m - Barrage J6
A1: Message Number | B1: Subcarrier Spacing | C1: Symbol time | D1: Subcarriers (FFT) | E1: CP length | F1: Average Recieved Power (mW) | G1: Threshold | H1: SNR | I1: Average Signal Power 2 | J1: Average Noise Power
A2: 1 | B2: 488.281 | C2: 0.002048 | D2: 512 | E2: 64 | F2: 289.683 | G2: 1 | H2: -2.41688 | I2: -8.82863 | J2: -6.41175
A3: =A2+1 -> 2 | B3: 488.281 | C3: 0.002048 | D3: 512 | E3: 64 | F3: 285.81 | G3: 1 | H3: -2.31161 | I3: -7.77167 | J3: -5.46006
A4: =A3+1 -> 3 | B4: 15625 | C4: 6.4e-05 | D4: 16 | E4: 64 | F4: 272.079 | G4: 1 | H4: -1.99596 | I4: -6.40908 | J4: -4.41312
A5: =A4+1 -> 4 | B5: 244.141 | C5: 0.004096 | D5: 1024 | E5: 64 | F5: 254.439 | G5: 1 | H5: -1.71636 | I5: -5.64688 | J5: -3.93053
A6: =A5+1 -> 5 | B6: 488.281 | C6: 0.002048 | D6: 512 | E6: 64 | F6: 241.025 | G6: 1 | H6: -1.37067 | I6: -4.90266 | J6: -3.53199
A7: =A6+1 -> 6 | B7: 488.281 | C7: 0.002048 | D7: 512 | E7: 64 | F7: 246.455 | G7: 1 | H7: -1.23471 | I7: -4.65136 | J7: -3.41665
A8: =A7+1 -> 7 | B8: 488.281 | C8: 0.002048 | D8: 512 | E8: 64 | F8: 246.735 | G8: 1 | H8: -0.99992 | I8: -4.21933 | J8: -3.21941
A9: =A8+1 -> 8 | B9: 3906.25 | C9: 0.000256 | D9: 64 | E9: 64 | F9: 262.52 | G9: 1 | H9: -0.80891 | I9: -3.8616 | J9: -3.05269
A10: =A9+1 -> 9 | B10: 244.141 | C10: 0.004096 | D10: 1024 | E10: 64 | F10: 277.408 | G10: 1 | H10: -0.723664 | I10: -3.70133 | J10: -2.97767
A11: =A10+1 -> 10 | B11: 488.281 | C11: 0.002048 | D11: 512 | E11: 64 | F11: 270.838 | G11: 1 | H11: -0.567213 | I11: -3.39467 | J11: -2.82745
A12: =A11+1 -> 11 | B12: 244.141 | C12: 0.004096 | D12: 1024 | E12: 64 | F12: 291.315 | G12: 1 | H12: -0.392245 | I12: -3.15011 | J12: -2.75787
A13: =A12+1 -> 12 | B13: 976.562 | C13: 0.001024 | D13: 256 | E13: 64 | F13: 257.039 | G13: 1 | H13: -0.204364 | I13: -2.96199 | J13: -2.75763
A14: =A13+1 -> 13 | B14: 488.281 | C14: 0.002048 | D14: 512 | E14: 64 | F14: 237.117 | G14: 1 | H14: -0.109396 | I14: -2.88214 | J14: -2.77274
... A140: =A139+1 -> 139 | B140: 488.281 | C140: 0.002048 | D140: 512 | E140: 64 | F140: 292.919 | G140: 1 | H140: 5.31294 | I140: -0.493132 | J140: -5.80607

Sheet 0.5m - Barrage J7
A1: Message Number | B1: Subcarrier Spacing | C1: Symbol time | D1: Subcarriers (FFT) | E1: CP length | F1: Average Recieved Power (mW) | G1: Threshold | H1: SNR | I1: Average Signal Power 2 | J1: Average Noise Power
A2: 1 | B2: 488.281 | C2: 0.002048 | D2: 512 | E2: 64 | F2: 306.026 | G2: 1 | H2: -2.54759 | I2: -8.79603 | J2: -6.24844
A3: =A2+1 -> 2 | B3: 244.141 | C3: 0.004096 | D3: 1024 | E3: 64 | F3: 286.277 | G3: 1 | H3: -2.38744 | I3: -7.78682 | J3: -5.39938
A4: =A3+1 -> 3 | B4: 244.141 | C4: 0.004096 | D4: 1024 | E4: 64 | F4: 240.594 | G4: 1 | H4: -2.02451 | I4: -6.50007 | J4: -4.47556
A5: =A4+1 -> 4 | B5: 488.281 | C5: 0.002048 | D5: 512 | E5: 64 | F5: 219.352 | G5: 1 | H5: -1.68111 | I5: -5.66513 | J5: -3.98402
A6: =A5+1 -> 5 | B6: 488.281 | C6: 0.002048 | D6: 512 | E6: 64 | F6: 230.205 | G6: 1 | H6: -1.38309 | I6: -5.03546 | J6: -3.65237
A7: =A6+1 -> 6 | B7: 244.141 | C7: 0.004096 | D7: 1024 | E7: 64 | F7: 245.428 | G7: 1 | H7: -1.2514 | I7: -4.76593 | J7: -3.51453
A8: =A7+1 -> 7 | B8: 3906.25 | C8: 0.000256 | D8: 64 | E8: 32 | F8: 258.908 | G8: 1 | H8: -1.03353 | I8: -4.2825 | J8: -3.24897
A9: =A8+1 -> 8 | B9: 244.141 | C9: 0.004096 | D9: 1024 | E9: 64 | F9: 290.314 | G9: 1 | H9: -0.863589 | I9: -3.87141 | J9: -3.00782
A10: =A9+1 -> 9 | B10: 244.141 | C10: 0.004096 | D10: 1024 | E10: 64 | F10: 297.526 | G10: 1 | H10: -0.789676 | I10: -3.68851 | J10: -2.89883
A11: =A10+1 -> 10 | B11: 488.281 | C11: 0.002048 | D11: 512 | E11: 64 | F11: 301.729 | G11: 1 | H11: -0.631867 | I11: -3.38242 | J11: -2.75056
A12: =A11+1 -> 11 | B12: 488.281 | C12: 0.002048 | D12: 512 | E12: 64 | F12: 294.022 | G12: 1 | H12: -0.457863 | I12: -3.12739 | J12: -2.66952
A13: =A12+1 -> 12 | B13: 244.141 | C13: 0.004096 | D13: 1024 | E13: 64 | F13: 283.367 | G13: 1 | H13: -0.267351 | I13: -2.91617 | J13: -2.64882
A14: =A13+1 -> 13 | B14: 244.141 | C14: 0.004096 | D14: 1024 | E14: 64 | F14: 264.463 | G14: 1 | H14: -0.167957 | I14: -2.82537 | J14: -2.65741
... A140: =A139+1 -> 139 | B140: 488.281 | C140: 0.002048 | D140: 512 | E140: 64 | F140: 312.125 | G140: 1 | H140: 5.40091 | I140: -0.443107 | J140: -5.84402

Sheet 0.5m - Barrage J8
A1: Message Number | B1: Subcarrier Spacing | C1: Symbol time | D1: Subcarriers (FFT) | E1: CP length | F1: Average Recieved Power (mW) | G1: Threshold | H1: SNR | I1: Average Signal Power 2 | J1: Average Noise Power
A2: 1 | B2: 488.281 | C2: 0.002048 | D2: 512 | E2: 64 | F2: 242.17 | G2: 1 | H2: -2.44918 | I2: -8.99099 | J2: -6.54182
A3: =A2+1 -> 2 | B3: 488.281 | C3: 0.002048 | D3: 512 | E3: 64 | F3: 268.119 | G3: 1 | H3: -2.30494 | I3: -7.95665 | J3: -5.65171
A4: =A3+1 -> 3 | B4: 488.281 | C4: 0.002048 | D4: 512 | E4: 64 | F4: 239.015 | G4: 1 | H4: -1.97092 | I4: -6.60613 | J4: -4.63521
A5: =A4+1 -> 4 | B5: 244.141 | C5: 0.004096 | D5: 1024 | E5: 64 | F5: 238.798 | G5: 1 | H5: -1.6497 | I5: -5.6982 | J5: -4.0485
A6: =A5+1 -> 5 | B6: 488.281 | C6: 0.002048 | D6: 512 | E6: 64 | F6: 242.246 | G6: 1 | H6: -1.36852 | I6: -5.03694 | J6: -3.66842
A7: =A6+1 -> 6 | B7: 244.141 | C7: 0.004096 | D7: 1024 | E7: 64 | F7: 255.239 | G7: 1 | H7: -1.23947 | I7: -4.75563 | J7: -3.51617
A8: =A7+1 -> 7 | B8: 244.141 | C8: 0.004096 | D8: 1024 | E8: 64 | F8: 263.241 | G8: 1 | H8: -1.02125 | I8: -4.26494 | J8: -3.2437
A9: =A8+1 -> 8 | B9: 488.281 | C9: 0.002048 | D9: 512 | E9: 64 | F9: 293.566 | G9: 1 | H9: -0.847757 | I9: -3.84983 | J9: -3.00207
A10: =A9+1 -> 9 | B10: 488.281 | C10: 0.002048 | D10: 512 | E10: 64 | F10: 303.65 | G10: 1 | H10: -0.768413 | I10: -3.66966 | J10: -2.90124
A11: =A10+1 -> 10 | B11: 244.141 | C11: 0.004096 | D11: 1024 | E11: 64 | F11: 302.893 | G11: 1 | H11: -0.604162 | I11: -3.36622 | J11: -2.76206
A12: =A11+1 -> 11 | B12: 3906.25 | C12: 0.000256 | D12: 64 | E12: 64 | F12: 296.306 | G12: 1 | H12: -0.436742 | I12: -3.10491 | J12: -2.66817
A13: =A12+1 -> 12 | B13: 3906.25 | C13: 0.000256 | D13: 64 | E13: 8 | F13: 278.886 | G13: 1 | H13: -0.248238 | I13: -2.89638 | J13: -2.64814
A14: =A13+1 -> 13 | B14: 488.281 | C14: 0.002048 | D14: 512 | E14: 64 | F14: 260.909 | G14: 1 | H14: -0.150928 | I14: -2.80668 | J14: -2.65575
... A144: =A143+1 -> 143 | B144: 976.562 | C144: 0.001024 | D144: 256 | E144: 32 | F144: 232.102 | G144: 1 | H144: 5.37574 | I144: -0.467253 | J144: -5.84299

Sheet 0.5m - Tone J1
A1: Message Number | B1: Subcarrier Spacing | C1: Symbol time | D1: Subcarriers (FFT) | E1: CP length | F1: Average Recieved Power (mW) | G1: Threshold | H1: SNR | I1: Average Signal Power 2 | J1: Average Noise Power
A2: 1 | B2: 488.281 | C2: 0.002048 | D2: 512 | E2: 64 | F2: 355.337 | G2: 1 | H2: -2.78569 | I2: -8.43663 | J2: -5.65094
A3: =A2+1 -> 2 | B3: 976.562 | C3: 0.001024 | D3: 256 | E3: 64 | F3: 333.457 | G3: 1 | H3: -2.59633 | I3: -7.39568 | J3: -4.79935
A4: =A3+1 -> 3 | B4: 244.141 | C4: 0.004096 | D4: 1024 | E4: 64 | F4: 293.413 | G4: 1 | H4: -2.19091 | I4: -6.06043 | J4: -3.86952
A5: =A4+1 -> 4 | B5: 244.141 | C5: 0.004096 | D5: 1024 | E5: 64 | F5: 269.377 | G5: 1 | H5: -1.80372 | I5: -5.20935 | J5: -3.40563
A6: =A5+1 -> 5 | B6: 244.141 | C6: 0.004096 | D6: 1024 | E6: 64 | F6: 261.993 | G6: 1 | H6: -1.4636 | I6: -4.58608 | J6: -3.12248
A7: =A6+1 -> 6 | B7: 244.141 | C7: 0.004096 | D7: 1024 | E7: 64 | F7: 275.852 | G7: 1 | H7: -1.31318 | I7: -4.32626 | J7: -3.01307
A8: =A7+1 -> 7 | B8: 244.141 | C8: 0.004096 | D8: 1024 | E8: 64 | F8: 290.285 | G8: 1 | H8: -1.06444 | I8: -3.85813 | J8: -2.79369
A9: =A8+1 -> 8 | B9: 244.141 | C9: 0.004096 | D9: 1024 | E9: 64 | F9: 329.506 | G9: 1 | H9: -0.876326 | I9: -3.4468 | J9: -2.57047
A10: =A9+1 -> 9 | B10: 244.141 | C10: 0.004096 | D10: 1024 | E10: 64 | F10: 344.153 | G10: 1 | H10: -0.798489 | I10: -3.25953 | J10: -2.46104
A11: =A10+1 -> 10 | B11: 244.141 | C11: 0.004096 | D11: 1024 | E11: 64 | F11: 349.613 | G11: 1 | H11: -0.634383 | I11: -2.93646 | J11: -2.30208
A12: =A11+1 -> 11 | B12: 244.141 | C12: 0.004096 | D12: 1024 | E12: 64 | F12: 352.893 | G12: 1 | H12: -0.437557 | I12: -2.68421 | J12: -2.24665
A13: =A12+1 -> 12 | B13: 244.141 | C13: 0.004096 | D13: 1024 | E13: 64 | F13: 306.486 | G13: 1 | H13: -0.220805 | I13: -2.49005 | J13: -2.26924
A14: =A13+1 -> 13 | B14: 244.141 | C14: 0.004096 | D14: 1024 | E14: 64 | F14: 268.616 | G14: 1 | H14: -0.110053 | I14: -2.4103 | J14: -2.30024
... A141: =A140+1 -> 140 | B141: 976.562 | C141: 0.001024 | D141: 256 | E141: 64 | F141: 319.947 | G141: 1 | H141: 6.96498 | I141: -0.0451901 | J141: -7.01017

Sheet 0.5m - Tone J2
A1: Message Number | B1: Subcarrier Spacing | C1: Symbol time | D1: Subcarriers (FFT) | E1: CP length | F1: Average Recieved Power (mW) | G1: Threshold | H1: SNR | I1: Average Signal Power 2 | J1: Average Noise Power
A2: 1 | B2: 488.281 | C2: 0.002048 | D2: 512 | E2: 64 | F2: 347.521 | G2: 1 | H2: -2.77387 | I2: -8.42786 | J2: -5.65399
A3: =A2+1 -> 2 | B3: 976.562 | C3: 0.001024 | D3: 256 | E3: 32 | F3: 321.928 | G3: 1 | H3: -2.59703 | I3: -7.37661 | J3: -4.77958
A4: =A3+1 -> 3 | B4: 488.281 | C4: 0.002048 | D4: 512 | E4: 64 | F4: 302.81 | G4: 1 | H4: -2.25361 | I4: -6.20382 | J4: -3.95021
A5: =A4+1 -> 4 | B5: 488.281 | C5: 0.002048 | D5: 512 | E5: 64 | F5: 269.565 | G5: 1 | H5: -1.80295 | I5: -5.20423 | J5: -3.40129
A6: =A5+1 -> 5 | B6: 488.281 | C6: 0.002048 | D6: 512 | E6: 64 | F6: 261.442 | G6: 1 | H6: -1.46385 | I6: -4.58209 | J6: -3.11824
A7: =A6+1 -> 6 | B7: 488.281 | C7: 0.002048 | D7: 512 | E7: 64 | F7: 281.75 | G7: 1 | H7: -1.31882 | I7: -4.31531 | J7: -2.99648
A8: =A7+1 -> 7 | B8: 488.281 | C8: 0.002048 | D8: 512 | E8: 64 | F8: 286.506 | G8: 1 | H8: -1.0635 | I8: -3.85393 | J8: -2.79043
A9: =A8+1 -> 8 | B9: 488.281 | C9: 0.002048 | D9: 512 | E9: 64 | F9: 312.825 | G9: 1 | H9: -0.863453 | I9: -3.44889 | J9: -2.58543
A10: =A9+1 -> 9 | B10: 488.281 | C10: 0.002048 | D10: 512 | E10: 64 | F10: 340.551 | G10: 1 | H10: -0.782055 | I10: -3.26411 | J10: -2.48205
A11: =A10+1 -> 10 | B11: 488.281 | C11: 0.002048 | D11: 512 | E11: 64 | F11: 341.135 | G11: 1 | H11: -0.610892 | I11: -2.9515 | J11: -2.34061
A12: =A11+1 -> 11 | B12: 488.281 | C12: 0.002048 | D12: 512 | E12: 64 | F12: 350.153 | G12: 1 | H12: -0.415818 | I12: -2.6998 | J12: -2.28398
A13: =A12+1 -> 12 | B13: 488.281 | C13: 0.002048 | D13: 512 | E13: 64 | F13: 313.19 | G13: 1 | H13: -0.199835 | I13: -2.50708 | J13: -2.30724
A14: =A13+1 -> 13 | B14: 488.281 | C14: 0.002048 | D14: 512 | E14: 64 | F14: 279.266 | G14: 1 | H14: -0.0899513 | I14: -2.42586 | J14: -2.33591
... A140: =A139+1 -> 139 | B140: 488.281 | C140: 0.002048 | D140: 512 | E140: 64 | F140: 385.145 | G140: 1 | H140: 7.07711 | I140: -0.0114407 | J140: -7.08855

Sheet 0.5m - Tone J3
A1: Message Number | B1: Subcarrier Spacing | C1: Symbol time | D1: Subcarriers (FFT) | E1: CP length | F1: Average Recieved Power (mW) | G1: Threshold | H1: SNR | I1: Average Signal Power 2 | J1: Average Noise Power
A2: 1 | B2: 488.281 | C2: 0.002048 | D2: 512 | E2: 64 | F2: 372.495 | G2: 1 | H2: -2.83507 | I2: -8.23269 | J2: -5.39762
A3: =A2+1 -> 2 | B3: 1953.12 | C3: 0.000512 | D3: 128 | E3: 16 | F3: 357.168 | G3: 1 | H3: -2.65448 | I3: -7.21965 | J3: -4.56518
A4: =A3+1 -> 3 | B4: 488.281 | C4: 0.002048 | D4: 512 | E4: 64 | F4: 308.459 | G4: 1 | H4: -2.25267 | I4: -5.91349 | J4: -3.66083
A5: =A4+1 -> 4 | B5: 488.281 | C5: 0.002048 | D5: 512 | E5: 64 | F5: 275.534 | G5: 1 | H5: -1.8579 | I5: -5.08825 | J5: -3.23035
A6: =A5+1 -> 5 | B6: 244.141 | C6: 0.004096 | D6: 1024 | E6: 64 | F6: 261.604 | G6: 1 | H6: -1.50542 | I6: -4.48982 | J6: -2.98439
A7: =A6+1 -> 6 | B7: 244.141 | C7: 0.004096 | D7: 1024 | E7: 64 | F7: 274.752 | G7: 1 | H7: -1.35129 | I7: -4.23647 | J7: -2.88517
A8: =A7+1 -> 7 | B8: 244.141 | C8: 0.004096 | D8: 1024 | E8: 64 | F8: 285.394 | G8: 1 | H8: -1.08954 | I8: -3.78475 | J8: -2.69521
A9: =A8+1 -> 8 | B9: 244.141 | C9: 0.004096 | D9: 1024 | E9: 64 | F9: 333.365 | G9: 1 | H9: -0.891636 | I9: -3.38108 | J9: -2.48944
A10: =A9+1 -> 9 | B10: 244.141 | C10: 0.004096 | D10: 1024 | E10: 64 | F10: 400.592 | G10: 1 | H10: -0.821856 | I10: -3.20059 | J10: -2.37874
A11: =A10+1 -> 10 | B11: 244.141 | C11: 0.004096 | D11: 1024 | E11: 64 | F11: 380.386 | G11: 1 | H11: -0.648864 | I11: -2.87475 | J11: -2.22588
A12: =A11+1 -> 11 | B12: 488.281 | C12: 0.002048 | D12: 512 | E12: 64 | F12: 348.979 | G12: 1 | H12: -0.446583 | I12: -2.62784 | J12: -2.18126
A13: =A12+1 -> 12 | B13: 488.281 | C13: 0.002048 | D13: 512 | E13: 64 | F13: 303.302 | G13: 1 | H13: -0.223516 | I13: -2.4413 | J13: -2.21779
A14: =A13+1 -> 13 | B14: 488.281 | C14: 0.002048 | D14: 512 | E14: 64 | F14: 274.557 | G14: 1 | H14: -0.110671 | I14: -2.36417 | J14: -2.2535
... A140: =A139+1 -> 139 | B140: 488.281 | C140: 0.002048 | D140: 512 | E140: 64 | F140: 366.407 | G140: 1 | H140: 6.96248 | I140: 0.0165617 | J140: -6.94591

Sheet 0.5m - Tone J4
A1: Message Number | B1: Subcarrier Spacing | C1: Symbol time | D1: Subcarriers (FFT) | E1: CP length | F1: Average Recieved Power (mW) | G1: Threshold | H1: SNR | I1: Average Signal Power 2 | J1: Average Noise Power
A2: 1 | B2: 488.281 | C2: 0.002048 | D2: 512 | E2: 64 | F2: 368.394 | G2: 1 | H2: -2.45267 | I2: -7.34302 | J2: -4.89036
A3: =A2+1 -> 2 | B3: 488.281 | C3: 0.002048 | D3: 512 | E3: 64 | F3: 342.353 | G3: 1 | H3: -2.30494 | I3: -6.52968 | J3: -4.22474
A4: =A3+1 -> 3 | B4: 488.281 | C4: 0.002048 | D4: 512 | E4: 64 | F4: 282.46 | G4: 1 | H4: -1.93493 | I4: -5.46838 | J4: -3.53346
A5: =A4+1 -> 4 | B5: 488.281 | C5: 0.002048 | D5: 512 | E5: 64 | F5: 265.759 | G5: 1 | H5: -1.56667 | I5: -4.74529 | J5: -3.17861
A6: =A5+1 -> 5 | B6: 488.281 | C6: 0.002048 | D6: 512 | E6: 64 | F6: 264.883 | G6: 1 | H6: -1.23883 | I6: -4.20244 | J6: -2.96361
A7: =A6+1 -> 6 | B7: 488.281 | C7: 0.002048 | D7: 512 | E7: 64 | F7: 280.127 | G7: 1 | H7: -1.09379 | I7: -3.97071 | J7: -2.87692
A8: =A7+1 -> 7 | B8: 488.281 | C8: 0.002048 | D8: 512 | E8: 64 | F8: 313.727 | G8: 1 | H8: -0.854986 | I8: -3.55638 | J8: -2.7014
A9: =A8+1 -> 8 | B9: 488.281 | C9: 0.002048 | D9: 512 | E9: 64 | F9: 348.218 | G9: 1 | H9: -0.680019 | I9: -3.17167 | J9: -2.49165
A10: =A9+1 -> 9 | B10: 488.281 | C10: 0.002048 | D10: 512 | E10: 64 | F10: 359.71 | G10: 1 | H10: -0.606249 | I10: -3.00702 | J10: -2.40077
A11: =A10+1 -> 10 | B11: 488.281 | C11: 0.002048 | D11: 512 | E11: 64 | F11: 377.277 | G11: 1 | H11: -0.435518 | I11: -2.70418 | J11: -2.26866
A12: =A11+1 -> 11 | B12: 488.281 | C12: 0.002048 | D12: 512 | E12: 64 | F12: 326.707 | G12: 1 | H12: -0.236453 | I12: -2.47488 | J12: -2.23842
A13: =A12+1 -> 12 | B13: 488.281 | C13: 0.002048 | D13: 512 | E13: 64 | F13: 304.746 | G13: 1 | H13: -0.0160245 | I13: -2.30149 | J13: -2.28547
A14: =A13+1 -> 13 | B14: 488.281 | C14: 0.002048 | D14: 512 | E14: 64 | F14: 272.621 | G14: 1 | H14: 0.095395 | I14: -2.22895 | J14: -2.32434
... A141: =A140+1 -> 140 | B141: 488.281 | C141: 0.002048 | D141: 512 | E141: 64 | F141: 320.833 | G141: 1 | H141: 7.1328 | I141: 0.0307874 | J141: -7.10201

Sheet 0.5m - Tone J5
A1: Message Number | B1: Subcarrier Spacing | C1: Symbol time | D1: Subcarriers (FFT) | E1: CP length | F1: Average Recieved Power (mW) | G1: Threshold | H1: SNR | I1: Average Signal Power 2 | J1: Average Noise Power
A2: 1 | B2: 488.281 | C2: 0.002048 | D2: 512 | E2: 64 | F2: 380.412 | G2: 1 | H2: -2.88089 | I2: -8.23449 | J2: -5.35361
A3: =A2+1 -> 2 | B3: 1953.12 | C3: 0.000512 | D3: 128 | E3: 16 | F3: 357.002 | G3: 1 | H3: -2.70379 | I3: -7.20203 | J3: -4.49824
A4: =A3+1 -> 3 | B4: 488.281 | C4: 0.002048 | D4: 512 | E4: 64 | F4: 312.153 | G4: 1 | H4: -2.29159 | I4: -5.89413 | J4: -3.60254
A5: =A4+1 -> 4 | B5: 488.281 | C5: 0.002048 | D5: 512 | E5: 64 | F5: 276.738 | G5: 1 | H5: -1.88756 | I5: -5.07403 | J5: -3.18646
A6: =A5+1 -> 5 | B6: 976.562 | C6: 0.001024 | D6: 256 | E6: 32 | F6: 264.052 | G6: 1 | H6: -1.53108 | I6: -4.47676 | J6: -2.94569
A7: =A6+1 -> 6 | B7: 488.281 | C7: 0.002048 | D7: 512 | E7: 64 | F7: 277.92 | G7: 1 | H7: -1.37644 | I7: -4.22229 | J7: -2.84585
A8: =A7+1 -> 7 | B8: 488.281 | C8: 0.002048 | D8: 512 | E8: 64 | F8: 287.089 | G8: 1 | H8: -1.11527 | I8: -3.76699 | J8: -2.65172
A9: =A8+1 -> 8 | B9: 488.281 | C9: 0.002048 | D9: 512 | E9: 64 | F9: 326.53 | G9: 1 | H9: -0.919343 | I9: -3.36131 | J9: -2.44197
A10: =A9+1 -> 9 | B10: 488.281 | C10: 0.002048 | D10: 512 | E10: 64 | F10: 361.42 | G10: 1 | H10: -0.844629 | I10: -3.17205 | J10: -2.32742
A11: =A10+1 -> 10 | B11: 976.562 | C11: 0.001024 | D11: 256 | E11: 64 | F11: 385.733 | G11: 1 | H11: -0.686051 | I11: -2.84699 | J11: -2.16094
A12: =A11+1 -> 11 | B12: 976.562 | C12: 0.001024 | D12: 256 | E12: 64 | F12: 369.056 | G12: 1 | H12: -0.498424 | I12: -2.59034 | J12: -2.09192
A13: =A12+1 -> 12 | B13: 488.281 | C13: 0.002048 | D13: 512 | E13: 64 | F13: 329.006 | G13: 1 | H13: -0.283367 | I13: -2.39608 | J13: -2.11271
A14: =A13+1 -> 13 | B14: 488.281 | C14: 0.002048 | D14: 512 | E14: 64 | F14: 288.501 | G14: 1 | H14: -0.17201 | I14: -2.31632 | J14: -2.14431
... A141: =A140+1 -> 140 | B141: 244.141 | C141: 0.004096 | D141: 1024 | E141: 64 | F141: 351.622 | G141: 1 | H141: 6.92537 | I141: 0.0420542 | J141: -6.88332

Sheet 0.5m - Tone J6
A1: Message Number | B1: Subcarrier Spacing | C1: Symbol time | D1: Subcarriers (FFT) | E1: CP length | F1: Average Recieved Power (mW) | G1: Threshold | H1: SNR | I1: Average Signal Power 2 | J1: Average Noise Power
A2: 1 | B2: 488.281 | C2: 0.002048 | D2: 512 | E2: 64 | F2: 368.394 | G2: 1 | H2: -2.45267 | I2: -7.34302 | J2: -4.89036
A3: =A2+1 -> 2 | B3: 488.281 | C3: 0.002048 | D3: 512 | E3: 64 | F3: 342.353 | G3: 1 | H3: -2.30494 | I3: -6.52968 | J3: -4.22474
A4: =A3+1 -> 3 | B4: 488.281 | C4: 0.002048 | D4: 512 | E4: 64 | F4: 282.46 | G4: 1 | H4: -1.93493 | I4: -5.46838 | J4: -3.53346
A5: =A4+1 -> 4 | B5: 488.281 | C5: 0.002048 | D5: 512 | E5: 64 | F5: 265.759 | G5: 1 | H5: -1.56667 | I5: -4.74529 | J5: -3.17861
A6: =A5+1 -> 5 | B6: 488.281 | C6: 0.002048 | D6: 512 | E6: 64 | F6: 264.883 | G6: 1 | H6: -1.23883 | I6: -4.20244 | J6: -2.96361
A7: =A6+1 -> 6 | B7: 488.281 | C7: 0.002048 | D7: 512 | E7: 64 | F7: 280.127 | G7: 1 | H7: -1.09379 | I7: -3.97071 | J7: -2.87692
A8: =A7+1 -> 7 | B8: 488.281 | C8: 0.002048 | D8: 512 | E8: 64 | F8: 313.727 | G8: 1 | H8: -0.854986 | I8: -3.55638 | J8: -2.7014
A9: =A8+1 -> 8 | B9: 488.281 | C9: 0.002048 | D9: 512 | E9: 64 | F9: 348.218 | G9: 1 | H9: -0.680019 | I9: -3.17167 | J9: -2.49165
A10: =A9+1 -> 9 | B10: 488.281 | C10: 0.002048 | D10: 512 | E10: 64 | F10: 359.71 | G10: 1 | H10: -0.606249 | I10: -3.00702 | J10: -2.40077
A11: =A10+1 -> 10 | B11: 488.281 | C11: 0.002048 | D11: 512 | E11: 64 | F11: 377.277 | G11: 1 | H11: -0.435518 | I11: -2.70418 | J11: -2.26866
A12: =A11+1 -> 11 | B12: 488.281 | C12: 0.002048 | D12: 512 | E12: 64 | F12: 326.707 | G12: 1 | H12: -0.236453 | I12: -2.47488 | J12: -2.23842
A13: =A12+1 -> 12 | B13: 488.281 | C13: 0.002048 | D13: 512 | E13: 64 | F13: 304.746 | G13: 1 | H13: -0.0160245 | I13: -2.30149 | J13: -2.28547
A14: =A13+1 -> 13 | B14: 488.281 | C14: 0.002048 | D14: 512 | E14: 64 | F14: 272.621 | G14: 1 | H14: 0.095395 | I14: -2.22895 | J14: -2.32434
... A141: =A140+1 -> 140 | B141: 488.281 | C141: 0.002048 | D141: 512 | E141: 64 | F141: 320.833 | G141: 1 | H141: 7.1328 | I141: 0.0307874 | J141: -7.10201

Sheet 0.5m - Tone J7
A1: Message Number | B1: Subcarrier Spacing | C1: Symbol time | D1: Subcarriers (FFT) | E1: CP length | F1: Average Recieved Power (mW) | G1: Threshold | H1: SNR | I1: Average Signal Power 2 | J1: Average Noise Power
A2: 1 | B2: 488.281 | C2: 0.002048 | D2: 512 | E2: 64 | F2: 362.401 | G2: 1 | H2: -2.82235 | I2: -8.73797 | J2: -5.91562
A3: =A2+1 -> 2 | B3: 976.562 | C3: 0.001024 | D3: 256 | E3: 16 | F3: 342.47 | G3: 1 | H3: -2.59149 | I3: -7.33076 | J3: -4.73927
A4: =A3+1 -> 3 | B4: 244.141 | C4: 0.004096 | D4: 1024 | E4: 64 | F4: 287.675 | G4: 1 | H4: -2.19207 | I4: -6.0029 | J4: -3.81083
A5: =A4+1 -> 4 | B5: 244.141 | C5: 0.004096 | D5: 1024 | E5: 64 | F5: 269.74 | G5: 1 | H5: -1.80966 | I5: -5.15402 | J5: -3.34436
A6: =A5+1 -> 5 | B6: 244.141 | C6: 0.004096 | D6: 1024 | E6: 64 | F6: 273.036 | G6: 1 | H6: -1.47131 | I6: -4.53407 | J6: -3.06276
A7: =A6+1 -> 6 | B7: 244.141 | C7: 0.004096 | D7: 1024 | E7: 64 | F7: 281.873 | G7: 1 | H7: -1.32337 | I7: -4.27339 | J7: -2.95002
A8: =A7+1 -> 7 | B8: 244.141 | C8: 0.004096 | D8: 1024 | E8: 64 | F8: 311.248 | G8: 1 | H8: -1.11454 | I8: -3.87285 | J8: -2.75831
A9: =A8+1 -> 8 | B9: 488.281 | C9: 0.002048 | D9: 512 | E9: 64 | F9: 352.804 | G9: 1 | H9: -0.889346 | I9: -3.39466 | J9: -2.50531
A10: =A9+1 -> 9 | B10: 244.141 | C10: 0.004096 | D10: 1024 | E10: 64 | F10: 368.247 | G10: 1 | H10: -0.807989 | I10: -3.20809 | J10: -2.40011
A11: =A10+1 -> 10 | B11: 976.562 | C11: 0.001024 | D11: 256 | E11: 32 | F11: 363.748 | G11: 1 | H11: -0.634134 | I11: -2.89093 | J11: -2.2568
A12: =A11+1 -> 11 | B12: 488.281 | C12: 0.002048 | D12: 512 | E12: 64 | F12: 351.605 | G12: 1 | H12: -0.490709 | I12: -2.70511 | J12: -2.2144
A13: =A12+1 -> 12 | B13: 244.141 | C13: 0.004096 | D13: 1024 | E13: 64 | F13: 310.54 | G13: 1 | H13: -0.214057 | I13: -2.44964 | J13: -2.23558
A14: =A13+1 -> 13 | B14: 244.141 | C14: 0.004096 | D14: 1024 | E14: 64 | F14: 279.577 | G14: 1 | H14: -0.103508 | I14: -2.36926 | J14: -2.26575
... A140: =A139+1 -> 139 | B140: 244.141 | C140: 0.004096 | D140: 1024 | E140: 64 | F140: 360.578 | G140: 1 | H140: 7.04745 | I140: -0.0116159 | J140: -7.05907

Sheet 0.5m - Tone J8
A1: Message Number | B1: Subcarrier Spacing | C1: Symbol time | D1: Subcarriers (FFT) | E1: CP length | F1: Average Recieved Power (mW) | G1: Threshold | H1: SNR | I1: Average Signal Power 2 | J1: Average Noise Power
A2: 1 | B2: 488.281 | C2: 0.002048 | D2: 512 | E2: 64 | F2: 345.324 | G2: 1 | H2: -2.80113 | I2: -8.51339 | J2: -5.71226
A3: =A2+1 -> 2 | B3: 1953.12 | C3: 0.000512 | D3: 128 | E3: 64 | F3: 310.511 | G3: 1 | H3: -2.60578 | I3: -7.46273 | J3: -4.85695
A4: =A3+1 -> 3 | B4: 488.281 | C4: 0.002048 | D4: 512 | E4: 64 | F4: 300.518 | G4: 1 | H4: -2.19977 | I4: -6.11059 | J4: -3.91081
A5: =A4+1 -> 4 | B5: 488.281 | C5: 0.002048 | D5: 512 | E5: 64 | F5: 266.248 | G5: 1 | H5: -1.81251 | I5: -5.25131 | J5: -3.4388
A6: =A5+1 -> 5 | B6: 488.281 | C6: 0.002048 | D6: 512 | E6: 64 | F6: 262.453 | G6: 1 | H6: -1.47275 | I6: -4.62063 | J6: -3.14789
A7: =A6+1 -> 6 | B7: 488.281 | C7: 0.002048 | D7: 512 | E7: 64 | F7: 270.587 | G7: 1 | H7: -1.32123 | I7: -4.35985 | J7: -3.03862
A8: =A7+1 -> 7 | B8: 488.281 | C8: 0.002048 | D8: 512 | E8: 64 | F8: 282.868 | G8: 1 | H8: -1.06516 | I8: -3.89581 | J8: -2.83066
A9: =A8+1 -> 8 | B9: 488.281 | C9: 0.002048 | D9: 512 | E9: 64 | F9: 319.877 | G9: 1 | H9: -0.86845 | I9: -3.48684 | J9: -2.61839
A10: =A9+1 -> 9 | B10: 488.281 | C10: 0.002048 | D10: 512 | E10: 64 | F10: 334.601 | G10: 1 | H10: -0.781809 | I10: -3.30385 | J10: -2.52204
A11: =A10+1 -> 10 | B11: 488.281 | C11: 0.002048 | D11: 512 | E11: 64 | F11: 365.806 | G11: 1 | H11: -0.61022 | I11: -2.98346 | J11: -2.37324
A12: =A11+1 -> 11 | B12: 488.281 | C12: 0.002048 | D12: 512 | E12: 64 | F12: 342.705 | G12: 1 | H12: -0.417668 | I12: -2.72945 | J12: -2.31178
A13: =A12+1 -> 12 | B13: 488.281 | C13: 0.002048 | D13: 512 | E13: 64 | F13: 296.914 | G13: 1 | H13: -0.203093 | I13: -2.53387 | J13: -2.33078
A14: =A13+1 -> 13 | B14: 488.281 | C14: 0.002048 | D14: 512 | E14: 64 | F14: 280.44 | G14: 1 | H14: -0.0939851 | I14: -2.45085 | J14: -2.35687
... A140: =A139+1 -> 139 | B140: 488.281 | C140: 0.002048 | D140: 512 | E140: 64 | F140: 354.639 | G140: 1 | H140: 6.92057 | I140: -0.0836598 | J140: -7.00423

Sheet 0.5m - Pulse J1
A1: Message Number | B1: Subcarrier Spacing | C1: Symbol time | D1: Subcarriers (FFT) | E1: CP length | F1: Average Recieved Power (mW) | G1: Threshold | H1: SNR | I1: Average Signal Power 2 | J1: Average Noise Power
A2: 1 | B2: 488.281 | C2: 0.002048 | D2: 512 | E2: 64 | F2: 8.69114 | G2: 1 | H2: 3.15271 | I2: -18.0976 | J2: -21.2503
A3: =A2+1 -> 2 | B3: 488.281 | C3: 0.002048 | D3: 512 | E3: 64 | F3: 8.32345 | G3: 1 | H3: 2.74727 | I3: -17.4141 | J3: -20.1614
A4: =A3+1 -> 3 | B4: 488.281 | C4: 0.002048 | D4: 512 | E4: 64 | F4: 7.97364 | G4: 1 | H4: 2.5072 | I4: -16.5596 | J4: -19.0668
A5: =A4+1 -> 4 | B5: 488.281 | C5: 0.002048 | D5: 512 | E5: 64 | F5: 6.66654 | G5: 1 | H5: 2.45676 | I5: -15.7901 | J5: -18.2468
A6: =A5+1 -> 5 | B6: 244.141 | C6: 0.004096 | D6: 1024 | E6: 64 | F6: 6.42194 | G6: 1 | H6: 2.45879 | I6: -15.2733 | J6: -17.732
A7: =A6+1 -> 6 | B7: 488.281 | C7: 0.002048 | D7: 512 | E7: 64 | F7: 6.72959 | G7: 1 | H7: 2.46082 | I7: -15.0351 | J7: -17.4959
A8: =A7+1 -> 7 | B8: 976.562 | C8: 0.001024 | D8: 256 | E8: 16 | F8: 7.2436 | G8: 1 | H8: 2.38196 | I8: -14.6236 | J8: -17.0055
A9: =A8+1 -> 8 | B9: 488.281 | C9: 0.002048 | D9: 512 | E9: 64 | F9: 9.04842 | G9: 1 | H9: 2.30329 | I9: -14.289 | J9: -16.5923
A10: =A9+1 -> 9 | B10: 488.281 | C10: 0.002048 | D10: 512 | E10: 64 | F10: 8.50542 | G10: 1 | H10: 2.26043 | I10: -14.1566 | J10: -16.417
A11: =A10+1 -> 10 | B11: 976.562 | C11: 0.001024 | D11: 256 | E11: 32 | F11: 8.9124 | G11: 1 | H11: 2.07239 | I11: -13.8818 | J11: -15.9542
A12: =A11+1 -> 11 | B12: 976.562 | C12: 0.001024 | D12: 256 | E12: 64 | F12: 13.1533 | G12: 1 | H12: 1.84852 | I12: -13.6329 | J12: -15.4814
A13: =A12+1 -> 12 | B13: 488.281 | C13: 0.002048 | D13: 512 | E13: 64 | F13: 12.8163 | G13: 1 | H13: 1.70416 | I13: -13.421 | J13: -15.1252
A14: =A13+1 -> 13 | B14: 244.141 | C14: 0.004096 | D14: 1024 | E14: 64 | F14: 11.4497 | G14: 1 | H14: 1.65714 | I14: -13.3296 | J14: -14.9868
... A142: =A141+1 -> 141 | B142: 488.281 | C142: 0.002048 | D142: 512 | E142: 64 | F142: 8.60067 | G142: 1 | H142: 0.702456 | I142: -10.8751 | J142: -11.5776

Sheet 0.5m - Pulse J2
A1: Message Number | B1: Subcarrier Spacing | C1: Symbol time | D1: Subcarriers (FFT) | E1: CP length | F1: Average Recieved Power (mW) | G1: Threshold | H1: SNR | I1: Average Signal Power 2 | J1: Average Noise Power
A2: 1 | B2: 488.281 | C2: 0.002048 | D2: 512 | E2: 64 | F2: 10.9624 | G2: 1 | H2: 3.75999 | I2: -18.3525 | J2: -22.1125
A3: =A2+1 -> 2 | B3: 488.281 | C3: 0.002048 | D3: 512 | E3: 64 | F3: 22.0079 | G3: 1 | H3: 1.51734 | I3: -15.563 | J3: -17.0804
A4: =A3+1 -> 3 | B4: 488.281 | C4: 0.002048 | D4: 512 | E4: 64 | F4: 23.0316 | G4: 1 | H4: 1.18072 | I4: -14.7742 | J4: -15.9549
A5: =A4+1 -> 4 | B5: 976.562 | C5: 0.001024 | D5: 256 | E5: 16 | F5: 21.739 | G5: 1 | H5: 1.00252 | I5: -13.6087 | J5: -14.6113
A6: =A5+1 -> 5 | B6: 488.281 | C6: 0.002048 | D6: 512 | E6: 64 | F6: 22.8781 | G6: 1 | H6: 1.00284 | I6: -12.7771 | J6: -13.78
A7: =A6+1 -> 6 | B7: 976.562 | C7: 0.001024 | D7: 256 | E7: 64 | F7: 21.1169 | G7: 1 | H7: 0.999951 | I7: -12.1794 | J7: -13.1793
A8: =A7+1 -> 7 | B8: 244.141 | C8: 0.004096 | D8: 1024 | E8: 64 | F8: 23.0676 | G8: 1 | H8: 0.986492 | I8: -11.9314 | J8: -12.9179
A9: =A8+1 -> 8 | B9: 976.562 | C9: 0.001024 | D9: 256 | E9: 64 | F9: 23.8286 | G9: 1 | H9: 0.959234 | I9: -11.5365 | J9: -12.4958
A10: =A9+1 -> 9 | B10: 488.281 | C10: 0.002048 | D10: 512 | E10: 64 | F10: 24.653 | G10: 1 | H10: 0.91621 | I10: -11.2223 | J10: -12.1385
A11: =A10+1 -> 10 | B11: 488.281 | C11: 0.002048 | D11: 512 | E11: 64 | F11: 22.4012 | G11: 1 | H11: 0.890031 | I11: -11.0719 | J11: -11.962
A12: =A11+1 -> 11 | B12: 976.562 | C12: 0.001024 | D12: 256 | E12: 32 | F12: 25.6771 | G12: 1 | H12: 0.9442 | I12: -10.8636 | J12: -11.8078
A13: =A12+1 -> 12 | B13: 244.141 | C13: 0.004096 | D13: 1024 | E13: 64 | F13: 12.5485 | G13: 1 | H13: 1.08446 | I13: -10.7245 | J13: -11.809
A14: =A13+1 -> 13 | B14: 976.562 | C14: 0.001024 | D14: 256 | E14: 64 | F14: 12.5925 | G14: 1 | H14: 1.22319 | I14: -10.6014 | J14: -11.8246
... A147: =A146+1 -> 146 | B147: 976.562 | C147: 0.001024 | D147: 256 | E147: 64 | F147: 20.7771 | G147: 1 | H147: 2.18648 | I147: -8.54565 | J147: -10.7321

Sheet 0.5m - Pulse J3
A1: Message Number | B1: Subcarrier Spacing | C1: Symbol time | D1: Subcarriers (FFT) | E1: CP length | F1: Average Recieved Power (mW) | G1: Threshold | H1: SNR | I1: Average Signal Power 2 | J1: Average Noise Power
A2: 1 | B2: 488.281 | C2: 0.002048 | D2: 512 | E2: 64 | F2: 19.5044 | G2: 1 | H2: 2.70415 | I2: -15.073 | J2: -17.7771
A3: =A2+1 -> 2 | B3: 1953.12 | C3: 0.000512 | D3: 128 | E3: 32 | F3: 17.6991 | G3: 1 | H3: 2.32614 | I3: -14.4896 | J3: -16.8157
A4: =A3+1 -> 3 | B4: 976.562 | C4: 0.001024 | D4: 256 | E4: 64 | F4: 17.1599 | G4: 1 | H4: 1.89246 | I4: -13.6197 | J4: -15.5121
A5: =A4+1 -> 4 | B5: 244.141 | C5: 0.004096 | D5: 1024 | E5: 64 | F5: 15.5681 | G5: 1 | H5: 1.6892 | I5: -13.0329 | J5: -14.7221
A6: =A5+1 -> 5 | B6: 488.281 | C6: 0.002048 | D6: 512 | E6: 64 | F6: 17.8884 | G6: 1 | H6: 1.56211 | I6: -12.5714 | J6: -14.1335
A7: =A6+1 -> 6 | B7: 244.141 | C7: 0.004096 | D7: 1024 | E7: 64 | F7: 15.9251 | G7: 1 | H7: 1.53581 | I7: -12.4019 | J7: -13.9377
A8: =A7+1 -> 7 | B8: 976.562 | C8: 0.001024 | D8: 256 | E8: 32 | F8: 18.6258 | G8: 1 | H8: 1.46391 | I8: -12.1082 | J8: -13.5721
A9: =A8+1 -> 8 | B9: 488.281 | C9: 0.002048 | D9: 512 | E9: 64 | F9: 19.7506 | G9: 1 | H9: 1.33452 | I9: -11.7891 | J9: -13.1236
A10: =A9+1 -> 9 | B10: 488.281 | C10: 0.002048 | D10: 512 | E10: 64 | F10: 17.8832 | G10: 1 | H10: 1.27273 | I10: -11.6583 | J10: -12.931
A11: =A10+1 -> 10 | B11: 976.562 | C11: 0.001024 | D11: 256 | E11: 64 | F11: 19.1323 | G11: 1 | H11: 1.29633 | I11: -11.4769 | J11: -12.7732
A12: =A11+1 -> 11 | B12: 244.141 | C12: 0.004096 | D12: 1024 | E12: 64 | F12: 12.274 | G12: 1 | H12: 1.38959 | I12: -11.3311 | J12: -12.7207
A13: =A12+1 -> 12 | B13: 976.562 | C13: 0.001024 | D13: 256 | E13: 64 | F13: 10.3568 | G13: 1 | H13: 1.48597 | I13: -11.2114 | J13: -12.6974
A14: =A13+1 -> 13 | B14: 1953.12 | C14: 0.000512 | D14: 128 | E14: 64 | F14: 10.025 | G14: 1 | H14: 1.53043 | I14: -11.1703 | J14: -12.7007
... A140: =A139+1 -> 139 | B140: 976.562 | C140: 0.001024 | D140: 256 | E140: 64 | F140: 22.1945 | G140: 1 | H140: 1.22946 | I140: -9.43843 | J140: -10.6679

Sheet 0.5m - Pulse J4
A1: Message Number | B1: Subcarrier Spacing | C1: Symbol time | D1: Subcarriers (FFT) | E1: CP length | F1: Average Recieved Power (mW) | G1: Threshold | H1: SNR | I1: Average Signal Power 2 | J1: Average Noise Power
A2: 1 | B2: 488.281 | C2: 0.002048 | D2: 512 | E2: 64 | F2: 1.77233 | G2: 1 | H2: 4.89374 | I2: -17.3631 | J2: -22.2569
A3: =A2+1 -> 2 | B3: 488.281 | C3: 0.002048 | D3: 512 | E3: 64 | F3: 17.7909 | G3: 1 | H3: 2.23952 | I3: -15.9168 | J3: -18.1563
A4: =A3+1 -> 3 | B4: 976.562 | C4: 0.001024 | D4: 256 | E4: 64 | F4: 15.7467 | G4: 1 | H4: 1.76163 | I4: -15.4144 | J4: -17.176
A5: =A4+1 -> 4 | B5: 976.562 | C5: 0.001024 | D5: 256 | E5: 16 | F5: 16.3036 | G5: 1 | H5: 1.27949 | I5: -14.6561 | J5: -15.9356
A6: =A5+1 -> 5 | B6: 488.281 | C6: 0.002048 | D6: 512 | E6: 64 | F6: 13.1576 | G6: 1 | H6: 1.0617 | I6: -14.1054 | J6: -15.1671
A7: =A6+1 -> 6 | B7: 976.562 | C7: 0.001024 | D7: 256 | E7: 64 | F7: 11.1992 | G7: 1 | H7: 0.929742 | I7: -13.7078 | J7: -14.6376
A8: =A7+1 -> 7 | B8: 976.562 | C8: 0.001024 | D8: 256 | E8: 64 | F8: 14.5026 | G8: 1 | H8: 0.874927 | I8: -13.5426 | J8: -14.4175
A9: =A8+1 -> 8 | B9: 488.281 | C9: 0.002048 | D9: 512 | E9: 64 | F9: 13.4086 | G9: 1 | H9: 0.771386 | I9: -13.2371 | J9: -14.0085
A10: =A9+1 -> 9 | B10: 244.141 | C10: 0.004096 | D10: 1024 | E10: 64 | F10: 16.0023 | G10: 1 | H10: 0.67863 | I10: -12.9814 | J10: -13.66
A11: =A10+1 -> 10 | B11: 488.281 | C11: 0.002048 | D11: 512 | E11: 64 | F11: 14.9014 | G11: 1 | H11: 0.635955 | I11: -12.8616 | J11: -13.4976
A12: =A11+1 -> 11 | B12: 488.281 | C12: 0.002048 | D12: 512 | E12: 64 | F12: 16.5733 | G12: 1 | H12: 0.588616 | I12: -12.6239 | J12: -13.2125
A13: =A12+1 -> 12 | B13: 488.281 | C13: 0.002048 | D13: 512 | E13: 64 | F13: 17.5767 | G13: 1 | H13: 0.575445 | I13: -12.3904 | J13: -12.9658
A14: =A13+1 -> 13 | B14: 488.281 | C14: 0.002048 | D14: 512 | E14: 64 | F14: 16.5758 | G14: 1 | H14: 0.589311 | I14: -12.1977 | J14: -12.787
... A141: =A140+1 -> 140 | B141: 976.562 | C141: 0.001024 | D141: 256 | E141: 64 | F141: 10.2084 | G141: 1 | H141: 1.1991 | I141: -10.3762 | J141: -11.5753

Sheet 0.5m - Pulse J5
A1: Message Number | B1: Subcarrier Spacing | C1: Symbol time | D1: Subcarriers (FFT) | E1: CP length | F1: Average Recieved Power (mW) | G1: Threshold | H1: SNR | I1: Average Signal Power 2 | J1: Average Noise Power
A2: 1 | B2: 488.281 | C2: 0.002048 | D2: 512 | E2: 64 | F2: 8.68681 | G2: 1 | H2: 3.89969 | I2: -16.8981 | J2: -20.7978
A3: =A2+1 -> 2 | B3: 244.141 | C3: 0.004096 | D3: 1024 | E3: 64 | F3: 8.51514 | G3: 1 | H3: 3.41064 | I3: -16.2786 | J3: -19.6892
A4: =A3+1 -> 3 | B4: 976.562 | C4: 0.001024 | D4: 256 | E4: 16 | F4: 8.2663 | G4: 1 | H4: 3.00165 | I4: -15.4209 | J4: -18.4225
A5: =A4+1 -> 4 | B5: 1953.12 | C5: 0.000512 | D5: 128 | E5: 32 | F5: 7.68955 | G5: 1 | H5: 2.88736 | I5: -14.8291 | J5: -17.7164
A6: =A5+1 -> 5 | B6: 244.141 | C6: 0.004096 | D6: 1024 | E6: 64 | F6: 8.24648 | G6: 1 | H6: 2.84999 | I6: -14.3585 | J6: -17.2085
A7: =A6+1 -> 6 | B7: 976.562 | C7: 0.001024 | D7: 256 | E7: 64 | F7: 8.50222 | G7: 1 | H7: 2.81177 | I7: -14.1633 | J7: -16.9751
A8: =A7+1 -> 7 | B8: 976.562 | C8: 0.001024 | D8: 256 | E8: 16 | F8: 8.32847 | G8: 1 | H8: 2.68864 | I8: -13.8291 | J8: -16.5177
A9: =A8+1 -> 8 | B9: 244.141 | C9: 0.004096 | D9: 1024 | E9: 64 | F9: 8.4969 | G9: 1 | H9: 2.56923 | I9: -13.5637 | J9: -16.133
A10: =A9+1 -> 9 | B10: 488.281 | C10: 0.002048 | D10: 512 | E10: 64 | F10: 9.96904 | G10: 1 | H10: 2.52526 | I10: -13.4427 | J10: -15.968
A11: =A10+1 -> 10 | B11: 976.562 | C11: 0.001024 | D11: 256 | E11: 32 | F11: 9.64982 | G11: 1 | H11: 2.22668 | I11: -13.1338 | J11: -15.3605
A12: =A11+1 -> 11 | B12: 976.562 | C12: 0.001024 | D12: 256 | E12: 64 | F12: 17.9036 | G12: 1 | H12: 1.88563 | I12: -12.7944 | J12: -14.6801
A13: =A12+1 -> 12 | B13: 976.562 | C13: 0.001024 | D13: 256 | E13: 16 | F13: 20.1326 | G13: 1 | H13: 1.65763 | I13: -12.5209 | J13: -14.1785
A14: =A13+1 -> 13 | B14: 976.562 | C14: 0.001024 | D14: 256 | E14: 64 | F14: 19.6761 | G14: 1 | H14: 1.56478 | I14: -12.3973 | J14: -13.9621
... A141: =A140+1 -> 140 | B141: 488.281 | C141: 0.002048 | D141: 512 | E141: 64 | F141: 18.1731 | G141: 1 | H141: 1.39478 | I141: -9.9724 | J141: -11.3672

Sheet 0.5m - Pulse J6
A1: Message Number | B1: Subcarrier Spacing | C1: Symbol time | D1: Subcarriers (FFT) | E1: CP length | F1: Average Recieved Power (mW) | G1: Threshold | H1: SNR | I1: Average Signal Power 2 | J1: Average Noise Power
A2: 1 | B2: 488.281 | C2: 0.002048 | D2: 512 | E2: 64 | F2: 7.66848 | G2: 1 | H2: 4.12951 | I2: -17.482 | J2: -21.6115
A3: =A2+1 -> 2 | B3: 1953.12 | C3: 0.000512 | D3: 128 | E3: 8 | F3: 7.35398 | G3: 1 | H3: 3.4973 | I3: -17.1104 | J3: -20.6077
A4: =A3+1 -> 3 | B4: 976.562 | C4: 0.001024 | D4: 256 | E4: 16 | F4: 6.65946 | G4: 1 | H4: 2.96041 | I4: -16.5461 | J4: -19.5065
A5: =A4+1 -> 4 | B5: 976.562 | C5: 0.001024 | D5: 256 | E5: 64 | F5: 6.47822 | G5: 1 | H5: 2.57225 | I5: -16.0015 | J5: -18.5737
A6: =A5+1 -> 5 | B6: 488.281 | C6: 0.002048 | D6: 512 | E6: 64 | F6: 6.08329 | G6: 1 | H6: 2.37673 | I6: -15.6358 | J6: -18.0125
A7: =A6+1 -> 6 | B7: 244.141 | C7: 0.004096 | D7: 1024 | E7: 64 | F7: 6.46326 | G7: 1 | H7: 2.29273 | I7: -15.4903 | J7: -17.7831
A8: =A7+1 -> 7 | B8: 976.562 | C8: 0.001024 | D8: 256 | E8: 32 | F8: 6.29203 | G8: 1 | H8: 2.11672 | I8: -15.1785 | J8: -17.2952
A9: =A8+1 -> 8 | B9: 488.281 | C9: 0.002048 | D9: 512 | E9: 64 | F9: 7.9534 | G9: 1 | H9: 1.92085 | I9: -14.93 | J9: -16.8508
A10: =A9+1 -> 9 | B10: 488.281 | C10: 0.002048 | D10: 512 | E10: 64 | F10: 7.66071 | G10: 1 | H10: 1.84064 | I10: -14.8211 | J10: -16.6617
A11: =A10+1 -> 10 | B11: 976.562 | C11: 0.001024 | D11: 256 | E11: 64 | F11: 9.19711 | G11: 1 | H11: 1.62457 | I11: -14.6235 | J11: -16.2481
A12: =A11+1 -> 11 | B12: 976.562 | C12: 0.001024 | D12: 256 | E12: 64 | F12: 10.0451 | G12: 1 | H12: 1.41239 | I12: -14.4527 | J12: -15.8651
A13: =A12+1 -> 12 | B13: 976.562 | C13: 0.001024 | D13: 256 | E13: 64 | F13: 9.25837 | G13: 1 | H13: 1.29736 | I13: -14.2922 | J13: -15.5896
A14: =A13+1 -> 13 | B14: 976.562 | C14: 0.001024 | D14: 256 | E14: 32 | F14: 8.47057 | G14: 1 | H14: 1.24441 | I14: -14.2361 | J14: -15.4805
... A142: =A141+1 -> 141 | B142: 488.281 | C142: 0.002048 | D142: 512 | E142: 64 | F142: 7.0335 | G142: 1 | H142: 1.01626 | I142: -12.6351 | J142: -13.6513

Sheet 0.5m - Pulse J7
A1: Message Number | B1: Subcarrier Spacing | C1: Symbol time | D1: Subcarriers (FFT) | E1: CP length | F1: Average Recieved Power (mW) | G1: Threshold | H1: SNR | I1: Average Signal Power 2 | J1: Average Noise Power
A2: 1 | B2: 488.281 | C2: 0.002048 | D2: 512 | E2: 64 | F2: 9.17584 | G2: 1 | H2: 3.20717 | I2: -17.8611 | J2: -21.0683
A3: =A2+1 -> 2 | B3: 1953.12 | C3: 0.000512 | D3: 128 | E3: 32 | F3: 8.7479 | G3: 1 | H3: 2.72932 | I3: -17.2011 | J3: -19.9304
A4: =A3+1 -> 3 | B4: 976.562 | C4: 0.001024 | D4: 256 | E4: 16 | F4: 8.54541 | G4: 1 | H4: 2.39629 | I4: -16.2281 | J4: -18.6244
A5: =A4+1 -> 4 | B5: 244.141 | C5: 0.004096 | D5: 1024 | E5: 64 | F5: 7.81756 | G5: 1 | H5: 2.31798 | I5: -15.5429 | J5: -17.8608
A6: =A5+1 -> 5 | B6: 244.141 | C6: 0.004096 | D6: 1024 | E6: 64 | F6: 7.77059 | G6: 1 | H6: 2.27529 | I6: -15.0296 | J6: -17.3049
A7: =A6+1 -> 6 | B7: 244.141 | C7: 0.004096 | D7: 1024 | E7: 64 | F7: 8.03231 | G7: 1 | H7: 2.24505 | I7: -14.8091 | J7: -17.0541
A8: =A7+1 -> 7 | B8: 976.562 | C8: 0.001024 | D8: 256 | E8: 16 | F8: 8.48565 | G8: 1 | H8: 2.14715 | I8: -14.4148 | J8: -16.562
A9: =A8+1 -> 8 | B9: 488.281 | C9: 0.002048 | D9: 512 | E9: 64 | F9: 9.6651 | G9: 1 | H9: 2.0228 | I9: -14.0935 | J9: -16.1163
A10: =A9+1 -> 9 | B10: 244.141 | C10: 0.004096 | D10: 1024 | E10: 64 | F10: 9.59253 | G10: 1 | H10: 1.97339 | I10: -13.9544 | J10: -15.9278
A11: =A10+1 -> 10 | B11: 244.141 | C11: 0.004096 | D11: 1024 | E11: 64 | F11: 9.83539 | G11: 1 | H11: 1.88568 | I11: -13.727 | J11: -15.6126
A12: =A11+1 -> 11 | B12: 244.141 | C12: 0.004096 | D12: 1024 | E12: 64 | F12: 9.17835 | G12: 1 | H12: 1.83661 | I12: -13.5325 | J12: -15.3691
A13: =A12+1 -> 12 | B13: 244.141 | C13: 0.004096 | D13: 1024 | E13: 64 | F13: 8.52096 | G13: 1 | H13: 1.81267 | I13: -13.3888 | J13: -15.2015
A14: =A13+1 -> 13 | B14: 244.141 | C14: 0.004096 | D14: 1024 | E14: 64 | F14: 7.53853 | G14: 1 | H14: 1.8171 | I14: -13.3247 | J14: -15.1418
... A140: =A139+1 -> 139 | B140: 244.141 | C140: 0.004096 | D140: 1024 | E140: 64 | F140: 9.78124 | G140: 1 | H140: 1.17016 | I140: -10.9493 | J140: -12.1195

Sheet 0.5m - Pulse J8
A1: Message Number | B1: Subcarrier Spacing | C1: Symbol time | D1: Subcarriers (FFT) | E1: CP length | F1: Average Recieved Power (mW) | G1: Threshold | H1: SNR | I1: Average Signal Power 2 | J1: Average Noise Power
A2: 1 | B2: 488.281 | C2: 0.002048 | D2: 512 | E2: 64 | F2: 12.9113 | G2: 1 | H2: 2.61655 | I2: -16.8847 | J2: -19.5012
A3: =A2+1 -> 2 | B3: 1953.12 | C3: 0.000512 | D3: 128 | E3: 64 | F3: 12.9789 | G3: 1 | H3: 2.29203 | I3: -16.1426 | J3: -18.4346
A4: =A3+1 -> 3 | B4: 488.281 | C4: 0.002048 | D4: 512 | E4: 64 | F4: 11.9864 | G4: 1 | H4: 2.03588 | I4: -15.0919 | J4: -17.1277
A5: =A4+1 -> 4 | B5: 488.281 | C5: 0.002048 | D5: 512 | E5: 64 | F5: 11.5379 | G5: 1 | H5: 1.97743 | I5: -14.3714 | J5: -16.3488
A6: =A5+1 -> 5 | B6: 244.141 | C6: 0.004096 | D6: 1024 | E6: 64 | F6: 11.1908 | G6: 1 | H6: 1.88064 | I6: -13.773 | J6: -15.6537
A7: =A6+1 -> 6 | B7: 488.281 | C7: 0.002048 | D7: 512 | E7: 64 | F7: 11.9268 | G7: 1 | H7: 1.85571 | I7: -13.5605 | J7: -15.4162
A8: =A7+1 -> 7 | B8: 976.562 | C8: 0.001024 | D8: 256 | E8: 32 | F8: 11.7719 | G8: 1 | H8: 1.80527 | I8: -13.1529 | J8: -14.9582
A9: =A8+1 -> 8 | B9: 244.141 | C9: 0.004096 | D9: 1024 | E9: 64 | F9: 13.8368 | G9: 1 | H9: 1.74532 | I9: -12.8126 | J9: -14.5579
A10: =A9+1 -> 9 | B10: 488.281 | C10: 0.002048 | D10: 512 | E10: 64 | F10: 13.5074 | G10: 1 | H10: 1.71994 | I10: -12.6677 | J10: -14.3877
A11: =A10+1 -> 10 | B11: 244.141 | C11: 0.004096 | D11: 1024 | E11: 64 | F11: 13.0586 | G11: 1 | H11: 1.57207 | I11: -12.3901 | J11: -13.9621
A12: =A11+1 -> 11 | B12: 488.281 | C12: 0.002048 | D12: 512 | E12: 64 | F12: 19.8669 | G12: 1 | H12: 1.39855 | I12: -12.133 | J12: -13.5315
A13: =A12+1 -> 12 | B13: 488.281 | C13: 0.002048 | D13: 512 | E13: 64 | F13: 19.0497 | G13: 1 | H13: 1.28109 | I13: -11.9113 | J13: -13.1924
A14: =A13+1 -> 13 | B14: 244.141 | C14: 0.004096 | D14: 1024 | E14: 64 | F14: 18.5475 | G14: 1 | H14: 1.23874 | I14: -11.808 | J14: -13.0467
... A140: =A139+1 -> 139 | B140: 488.281 | C140: 0.002048 | D140: 512 | E140: 64 | F140: 12.276 | G140: 1 | H140: 1.31317 | I140: -9.65424 | J140: -10.9674

Sheet 0.5m - Protocol Aware J1
A1: Message Number | B1: Subcarrier Spacing | C1: Symbol time | D1: Subcarriers (FFT) | E1: CP length | F1: Average Recieved Power (mW) | G1: Threshold | H1: SNR | I1: Average Signal Power 2 | J1: Average Noise Power
A2: 1 | B2: 488.281 | C2: 0.002048 | D2: 512 | E2: 64 | F2: 347.683 | G2: 1 | H2: -2.66321 | I2: -8.35152 | J2: -5.6883
A3: =A2+1 -> 2 | B3: 3906.25 | C3: 0.000256 | D3: 64 | E3: 64 | F3: 316.138 | G3: 1 | H3: -2.50211 | I3: -7.3298 | J3: -4.82769
A4: =A3+1 -> 3 | B4: 976.562 | C4: 0.001024 | D4: 256 | E4: 64 | F4: 292.978 | G4: 1 | H4: -2.11123 | I4: -6.02579 | J4: -3.91456
A5: =A4+1 -> 4 | B5: 244.141 | C5: 0.004096 | D5: 1024 | E5: 64 | F5: 259.485 | G5: 1 | H5: -1.73155 | I5: -5.22295 | J5: -3.49141
A6: =A5+1 -> 5 | B6: 976.562 | C6: 0.001024 | D6: 256 | E6: 64 | F6: 250.667 | G6: 1 | H6: -1.38671 | I6: -4.61758 | J6: -3.23087
A7: =A6+1 -> 6 | B7: 3906.25 | C7: 0.000256 | D7: 64 | E7: 16 | F7: 261.636 | G7: 1 | H7: -1.23709 | I7: -4.36101 | J7: -3.12392
A8: =A7+1 -> 7 | B8: 1953.12 | C8: 0.000512 | D8: 128 | E8: 32 | F8: 278.043 | G8: 1 | H8: -0.988015 | I8: -3.90238 | J8: -2.91436
A9: =A8+1 -> 8 | B9: 3906.25 | C9: 0.000256 | D9: 64 | E9: 16 | F9: 307.702 | G9: 1 | H9: -0.805743 | I9: -3.51345 | J9: -2.70771
A10: =A9+1 -> 9 | B10: 976.562 | C10: 0.001024 | D10: 256 | E10: 64 | F10: 333.426 | G10: 1 | H10: -0.726819 | I10: -3.33133 | J10: -2.60451
A11: =A10+1 -> 10 | B11: 244.141 | C11: 0.004096 | D11: 1024 | E11: 64 | F11: 335.321 | G11: 1 | H11: -0.594359 | I11: -3.04006 | J11: -2.4457
A12: =A11+1 -> 11 | B12: 1953.12 | C12: 0.000512 | D12: 128 | E12: 32 | F12: 312.155 | G12: 1 | H12: -0.448752 | I12: -2.83047 | J12: -2.38171
A13: =A12+1 -> 12 | B13: 488.281 | C13: 0.002048 | D13: 512 | E13: 64 | F13: 259.718 | G13: 1 | H13: -0.266662 | I13: -2.67493 | J13: -2.40827
A14: =A13+1 -> 13 | B14: 1953.12 | C14: 0.000512 | D14: 128 | E14: 64 | F14: 228.501 | G14: 1 | H14: -0.169899 | I14: -2.61131 | J14: -2.44142
... A142: =A141+1 -> 141 | B142: 244.141 | C142: 0.004096 | D142: 1024 | E142: 64 | F142: 290.292 | G142: 1 | H142: 4.02941 | I142: -0.643048 | J142: -4.67246

Sheet 0.5m - Protocol Aware J2
A1: Message Number | B1: Subcarrier Spacing | C1: Symbol time | D1: Subcarriers (FFT) | E1: CP length | F1: Average Recieved Power (mW) | G1: Threshold | H1: SNR | I1: Average Signal Power 2 | J1: Average Noise Power
A2: 1 | B2: 488.281 | C2: 0.002048 | D2: 512 | E2: 64 | F2: 314.074 | G2: 1 | H2: -2.79232 | I2: -8.81664 | J2: -6.02431
A3: =A2+1 -> 2 | B3: 488.281 | C3: 0.002048 | D3: 512 | E3: 64 | F3: 302.18 | G3: 1 | H3: -2.61128 | I3: -7.80061 | J3: -5.18933
A4: =A3+1 -> 3 | B4: 244.141 | C4: 0.004096 | D4: 1024 | E4: 64 | F4: 255.561 | G4: 1 | H4: -2.20583 | I4: -6.50513 | J4: -4.2993
A5: =A4+1 -> 4 | B5: 488.281 | C5: 0.002048 | D5: 512 | E5: 32 | F5: 223.803 | G5: 1 | H5: -1.87051 | I5: -5.79229 | J5: -3.92178
A6: =A5+1 -> 5 | B6: 244.141 | C6: 0.004096 | D6: 1024 | E6: 64 | F6: 215.99 | G6: 1 | H6: -1.52535 | I6: -5.16404 | J6: -3.6387
A7: =A6+1 -> 6 | B7: 488.281 | C7: 0.002048 | D7: 512 | E7: 64 | F7: 231.255 | G7: 1 | H7: -1.33696 | I7: -4.82111 | J7: -3.48414
A8: =A7+1 -> 7 | B8: 488.281 | C8: 0.002048 | D8: 512 | E8: 64 | F8: 245.741 | G8: 1 | H8: -1.11259 | I8: -4.35042 | J8: -3.23783
A9: =A8+1 -> 8 | B9: 244.141 | C9: 0.004096 | D9: 1024 | E9: 64 | F9: 292.24 | G9: 1 | H9: -0.967792 | I9: -3.92727 | J9: -2.95948
A10: =A9+1 -> 9 | B10: 488.281 | C10: 0.002048 | D10: 512 | E10: 64 | F10: 333.298 | G10: 1 | H10: -0.915289 | I10: -3.73046 | J10: -2.81517
A11: =A10+1 -> 10 | B11: 244.141 | C11: 0.004096 | D11: 1024 | E11: 64 | F11: 290.181 | G11: 1 | H11: -0.815757 | I11: -3.43775 | J11: -2.62199
A12: =A11+1 -> 11 | B12: 488.281 | C12: 0.002048 | D12: 512 | E12: 64 | F12: 267.782 | G12: 1 | H12: -0.707443 | I12: -3.24177 | J12: -2.53433
A13: =A12+1 -> 12 | B13: 1953.12 | C13: 0.000512 | D13: 128 | E13: 16 | F13: 229.5 | G13: 1 | H13: -0.558247 | I13: -3.10187 | J13: -2.54363
A14: =A13+1 -> 13 | B14: 976.562 | C14: 0.001024 | D14: 256 | E14: 32 | F14: 193.545 | G14: 1 | H14: -0.476767 | I14: -3.04637 | J14: -2.56961
... A140: =A139+1 -> 139 | B140: 244.141 | C140: 0.004096 | D140: 1024 | E140: 64 | F140: 339.634 | G140: 1 | H140: 4.02843 | I140: -0.628579 | J140: -4.65701

Sheet 0.5m - Protocol Aware J3
A1: Message Number | B1: Subcarrier Spacing | C1: Symbol time | D1: Subcarriers (FFT) | E1: CP length | F1: Average Recieved Power (mW) | G1: Threshold | H1: SNR | I1: Average Signal Power 2 | J1: Average Noise Power
A2: 1 | B2: 488.281 | C2: 0.002048 | D2: 512 | E2: 64 | F2: 309.556 | G2: 1 | H2: -2.16003 | I2: -8.36874 | J2: -6.20871
A3: =A2+1 -> 2 | B3: 976.562 | C3: 0.001024 | D3: 256 | E3: 16 | F3: 295.572 | G3: 1 | H3: -2.10478 | I3: -7.49175 | J3: -5.38697
A4: =A3+1 -> 3 | B4: 244.141 | C4: 0.004096 | D4: 1024 | E4: 64 | F4: 242.868 | G4: 1 | H4: -1.828 | I4: -6.35043 | J4: -4.52243
A5: =A4+1 -> 4 | B5: 7812.5 | C5: 0.000128 | D5: 32 | E5: 16 | F5: 207.286 | G5: 1 | H5: -1.50538 | I5: -5.62247 | J5: -4.11709
A6: =A5+1 -> 5 | B6: 244.141 | C6: 0.004096 | D6: 1024 | E6: 64 | F6: 201.253 | G6: 1 | H6: -1.22089 | I6: -5.07734 | J6: -3.85645
A7: =A6+1 -> 6 | B7: 488.281 | C7: 0.002048 | D7: 512 | E7: 64 | F7: 212.113 | G7: 1 | H7: -1.10255 | I7: -4.84391 | J7: -3.74135
A8: =A7+1 -> 7 | B8: 488.281 | C8: 0.002048 | D8: 512 | E8: 64 | F8: 229.094 | G8: 1 | H8: -0.930066 | I8: -4.41526 | J8: -3.48519
A9: =A8+1 -> 8 | B9: 244.141 | C9: 0.004096 | D9: 1024 | E9: 64 | F9: 271.426 | G9: 1 | H9: -0.839942 | I9: -4.03071 | J9: -3.19077
A10: =A9+1 -> 9 | B10: 244.141 | C10: 0.004096 | D10: 1024 | E10: 64 | F10: 292.641 | G10: 1 | H10: -0.808685 | I10: -3.85648 | J10: -3.0478
A11: =A10+1 -> 10 | B11: 976.562 | C11: 0.001024 | D11: 256 | E11: 32 | F11: 306.939 | G11: 1 | H11: -0.721175 | I11: -3.51741 | J11: -2.79623
A12: =A11+1 -> 11 | B12: 488.281 | C12: 0.002048 | D12: 512 | E12: 32 | F12: 327.43 | G12: 1 | H12: -0.569185 | I12: -3.22878 | J12: -2.6596
A13: =A12+1 -> 12 | B13: 488.281 | C13: 0.002048 | D13: 512 | E13: 64 | F13: 288.256 | G13: 1 | H13: -0.374053 | I13: -3.00892 | J13: -2.63486
A14: =A13+1 -> 13 | B14: 488.281 | C14: 0.002048 | D14: 512 | E14: 64 | F14: 253.942 | G14: 1 | H14: -0.269349 | I14: -2.91797 | J14: -2.64862
... A140: =A139+1 -> 139 | B140: 488.281 | C140: 0.002048 | D140: 512 | E140: 64 | F140: 288.535 | G140: 1 | H140: 3.43492 | I140: -0.818266 | J140: -4.25319

Sheet 0.5m - Protocol Aware J4
